2015-06-05 10:45:04,973 WARNING: to init Login Manager subsystem [in flask_app.py:47]
2015-06-05 10:49:48,654 WARNING: to init Login Manager subsystem [in flask_app.py:47]
2015-06-05 10:49:50,118 WARNING: to init Login Manager subsystem [in C:\Users\haribala\Documents\GitHub\my_lib_app\flask_app.py:47]
2015-06-05 10:59:07,164 WARNING: to init Login Manager subsystem [in flask_app.py:47]
2015-06-05 10:59:08,999 WARNING: to init Login Manager subsystem [in C:\Users\haribala\Documents\GitHub\my_lib_app\flask_app.py:47]
2015-06-05 10:59:45,276 WARNING: to init Login Manager subsystem [in flask_app.py:47]
2015-06-05 10:59:46,967 WARNING: to init Login Manager subsystem [in C:\Users\haribala\Documents\GitHub\my_lib_app\flask_app.py:47]
2015-06-05 11:04:32,901 WARNING: to init Login Manager subsystem [in flask_app.py:47]
2015-06-05 11:04:34,710 WARNING: to init Login Manager subsystem [in C:\Users\haribala\Documents\GitHub\my_lib_app\flask_app.py:47]
2015-06-05 11:04:35,148 WARNING: logging from library module [in C:\Users\haribala\Documents\GitHub\my_lib_app\library.py:13]
2015-06-05 11:09:03,099 WARNING: to init Login Manager subsystem [in flask_app.py:47]
2015-06-05 11:09:07,549 WARNING: to init Login Manager subsystem [in C:\Users\haribala\Documents\GitHub\my_lib_app\flask_app.py:47]
2015-06-05 11:09:07,987 WARNING: logging from library module [in C:\Users\haribala\Documents\GitHub\my_lib_app\library.py:13]
2015-06-05 11:10:31,806 WARNING: to init Login Manager subsystem [in flask_app.py:47]
2015-06-05 11:10:33,036 WARNING: to init Login Manager subsystem [in C:\Users\haribala\Documents\GitHub\my_lib_app\flask_app.py:47]
2015-06-05 11:10:33,394 WARNING: logging from library module [in C:\Users\haribala\Documents\GitHub\my_lib_app\library.py:13]
2015-06-05 11:12:34,201 WARNING: to init Login Manager subsystem [in flask_app.py:47]
2015-06-05 11:12:34,232 WARNING: to init Login Manager subsystem [in C:\Users\haribala\Documents\GitHub\my_lib_app\flask_app.py:47]
2015-06-05 11:12:34,232 WARNING: logging from library module [in C:\Users\haribala\Documents\GitHub\my_lib_app\library.py:13]
2015-06-05 11:15:27,381 WARNING: to init Login Manager subsystem [in flask_app.py:47]
2015-06-05 11:20:31,351 WARNING: to init Login Manager subsystem [in flask_app.py:47]
2015-06-05 11:21:30,009 WARNING: to init Login Manager subsystem [in flask_app.py:47]
2015-06-05 11:24:16,473 WARNING: to init Login Manager subsystem [in flask_app.py:47]
2015-06-05 11:38:11,858 WARNING: to init Login Manager subsystem [in flask_app.py:47]
2015-06-05 11:38:26,378 ERROR: Exception on /login2 [GET] [in c:\python27\lib\site-packages\flask\app.py:1423]
Traceback (most recent call last):
  File "c:\python27\lib\site-packages\flask\app.py", line 1817, in wsgi_app
    response = self.full_dispatch_request()
  File "c:\python27\lib\site-packages\flask\app.py", line 1477, in full_dispatch_request
    rv = self.handle_user_exception(e)
  File "c:\python27\lib\site-packages\flask\app.py", line 1381, in handle_user_exception
    reraise(exc_type, exc_value, tb)
  File "c:\python27\lib\site-packages\flask\app.py", line 1475, in full_dispatch_request
    rv = self.dispatch_request()
  File "c:\python27\lib\site-packages\flask\app.py", line 1461, in dispatch_request
    return self.view_functions[rule.endpoint](**req.view_args)
  File "flask_app.py", line 327, in gplus_login
    APPLICATION_NAME=APPLICATION_NAME))
  File "c:\python27\lib\site-packages\flask\templating.py", line 128, in render_template
    context, ctx.app)
  File "c:\python27\lib\site-packages\flask\templating.py", line 110, in _render
    rv = template.render(context)
  File "c:\python27\lib\site-packages\jinja2\environment.py", line 894, in render
    return self.environment.handle_exception(exc_info, True)
  File "C:\Users\haribala\Documents\GitHub\my_lib_app\templates\login.html", line 2, in top-level template code
    {% extends "base.html" %}
  File "C:\Users\haribala\Documents\GitHub\my_lib_app\templates\base.html", line 46, in top-level template code
    {% block content %}{% endblock %}
  File "C:\Users\haribala\Documents\GitHub\my_lib_app\templates\login.html", line 125, in block "content"
    {{ form.hidden_tag() }}
  File "c:\python27\lib\site-packages\jinja2\environment.py", line 372, in getattr
    return getattr(obj, attribute)
UndefinedError: 'form' is undefined
2015-06-05 11:40:28,358 WARNING: to init Login Manager subsystem [in flask_app.py:47]
2015-06-05 11:40:36,328 ERROR: Exception on /login2 [GET] [in c:\python27\lib\site-packages\flask\app.py:1423]
Traceback (most recent call last):
  File "c:\python27\lib\site-packages\flask\app.py", line 1817, in wsgi_app
    response = self.full_dispatch_request()
  File "c:\python27\lib\site-packages\flask\app.py", line 1477, in full_dispatch_request
    rv = self.handle_user_exception(e)
  File "c:\python27\lib\site-packages\flask\app.py", line 1381, in handle_user_exception
    reraise(exc_type, exc_value, tb)
  File "c:\python27\lib\site-packages\flask\app.py", line 1475, in full_dispatch_request
    rv = self.dispatch_request()
  File "c:\python27\lib\site-packages\flask\app.py", line 1461, in dispatch_request
    return self.view_functions[rule.endpoint](**req.view_args)
  File "flask_app.py", line 327, in gplus_login
    APPLICATION_NAME=APPLICATION_NAME))
  File "c:\python27\lib\site-packages\flask\templating.py", line 128, in render_template
    context, ctx.app)
  File "c:\python27\lib\site-packages\flask\templating.py", line 110, in _render
    rv = template.render(context)
  File "c:\python27\lib\site-packages\jinja2\environment.py", line 894, in render
    return self.environment.handle_exception(exc_info, True)
  File "C:\Users\haribala\Documents\GitHub\my_lib_app\templates\login.html", line 2, in top-level template code
    {% extends "base.html" %}
  File "C:\Users\haribala\Documents\GitHub\my_lib_app\templates\base.html", line 46, in top-level template code
    {% block content %}{% endblock %}
  File "C:\Users\haribala\Documents\GitHub\my_lib_app\templates\login.html", line 125, in block "content"
    {{ form.hidden_tag() }}
  File "c:\python27\lib\site-packages\jinja2\environment.py", line 372, in getattr
    return getattr(obj, attribute)
UndefinedError: 'form' is undefined
2015-06-05 11:41:14,901 WARNING: to init Login Manager subsystem [in flask_app.py:47]
2015-06-05 11:46:06,622 WARNING: to init Login Manager subsystem [in flask_app.py:47]
2015-06-05 11:46:27,744 ERROR: Exception on /login2 [GET] [in c:\python27\lib\site-packages\flask\app.py:1423]
Traceback (most recent call last):
  File "c:\python27\lib\site-packages\flask\app.py", line 1817, in wsgi_app
    response = self.full_dispatch_request()
  File "c:\python27\lib\site-packages\flask\app.py", line 1477, in full_dispatch_request
    rv = self.handle_user_exception(e)
  File "c:\python27\lib\site-packages\flask\app.py", line 1381, in handle_user_exception
    reraise(exc_type, exc_value, tb)
  File "c:\python27\lib\site-packages\flask\app.py", line 1475, in full_dispatch_request
    rv = self.dispatch_request()
  File "c:\python27\lib\site-packages\flask\app.py", line 1461, in dispatch_request
    return self.view_functions[rule.endpoint](**req.view_args)
  File "flask_app.py", line 328, in gplus_login
    APPLICATION_NAME=APPLICATION_NAME))
  File "c:\python27\lib\site-packages\flask\templating.py", line 128, in render_template
    context, ctx.app)
  File "c:\python27\lib\site-packages\flask\templating.py", line 110, in _render
    rv = template.render(context)
  File "c:\python27\lib\site-packages\jinja2\environment.py", line 894, in render
    return self.environment.handle_exception(exc_info, True)
  File "C:\Users\haribala\Documents\GitHub\my_lib_app\templates\login.html", line 2, in top-level template code
    {% extends "base.html" %}
  File "C:\Users\haribala\Documents\GitHub\my_lib_app\templates\base.html", line 46, in top-level template code
    {% block content %}{% endblock %}
  File "C:\Users\haribala\Documents\GitHub\my_lib_app\templates\login.html", line 125, in block "content"
    {{ form.hidden_tag() }}
  File "c:\python27\lib\site-packages\jinja2\environment.py", line 372, in getattr
    return getattr(obj, attribute)
UndefinedError: 'form' is undefined
2015-06-05 11:47:05,809 ERROR: Exception on /login2 [GET] [in c:\python27\lib\site-packages\flask\app.py:1423]
Traceback (most recent call last):
  File "c:\python27\lib\site-packages\flask\app.py", line 1817, in wsgi_app
    response = self.full_dispatch_request()
  File "c:\python27\lib\site-packages\flask\app.py", line 1477, in full_dispatch_request
    rv = self.handle_user_exception(e)
  File "c:\python27\lib\site-packages\flask\app.py", line 1381, in handle_user_exception
    reraise(exc_type, exc_value, tb)
  File "c:\python27\lib\site-packages\flask\app.py", line 1475, in full_dispatch_request
    rv = self.dispatch_request()
  File "c:\python27\lib\site-packages\flask\app.py", line 1461, in dispatch_request
    return self.view_functions[rule.endpoint](**req.view_args)
  File "flask_app.py", line 328, in gplus_login
    APPLICATION_NAME=APPLICATION_NAME))
  File "c:\python27\lib\site-packages\flask\templating.py", line 128, in render_template
    context, ctx.app)
  File "c:\python27\lib\site-packages\flask\templating.py", line 110, in _render
    rv = template.render(context)
  File "c:\python27\lib\site-packages\jinja2\environment.py", line 894, in render
    return self.environment.handle_exception(exc_info, True)
  File "C:\Users\haribala\Documents\GitHub\my_lib_app\templates\login.html", line 2, in top-level template code
    {% extends "base.html" %}
  File "C:\Users\haribala\Documents\GitHub\my_lib_app\templates\base.html", line 46, in top-level template code
    {% block content %}{% endblock %}
  File "C:\Users\haribala\Documents\GitHub\my_lib_app\templates\login.html", line 125, in block "content"
    {{ form.hidden_tag() }}
  File "c:\python27\lib\site-packages\jinja2\environment.py", line 372, in getattr
    return getattr(obj, attribute)
UndefinedError: 'form' is undefined
2015-06-05 11:49:55,977 WARNING: to init Login Manager subsystem [in flask_app.py:47]
2015-06-05 11:53:36,233 ERROR: Exception on /login2 [GET] [in c:\python27\lib\site-packages\flask\app.py:1423]
Traceback (most recent call last):
  File "c:\python27\lib\site-packages\flask\app.py", line 1817, in wsgi_app
    response = self.full_dispatch_request()
  File "c:\python27\lib\site-packages\flask\app.py", line 1477, in full_dispatch_request
    rv = self.handle_user_exception(e)
  File "c:\python27\lib\site-packages\flask\app.py", line 1381, in handle_user_exception
    reraise(exc_type, exc_value, tb)
  File "c:\python27\lib\site-packages\flask\app.py", line 1475, in full_dispatch_request
    rv = self.dispatch_request()
  File "c:\python27\lib\site-packages\flask\app.py", line 1461, in dispatch_request
    return self.view_functions[rule.endpoint](**req.view_args)
  File "flask_app.py", line 328, in gplus_login
    APPLICATION_NAME=APPLICATION_NAME))
  File "c:\python27\lib\bdb.py", line 55, in trace_dispatch
    return self.dispatch_exception(frame, arg)
  File "c:\python27\lib\bdb.py", line 97, in dispatch_exception
    if self.quitting: raise BdbQuit
BdbQuit
2015-06-05 11:59:28,013 WARNING: to init Login Manager subsystem [in flask_app.py:47]
2015-06-05 14:57:31,339 WARNING: to init Login Manager subsystem [in flask_app.py:47]
2015-06-06 17:37:15,957 WARNING: to init Login Manager subsystem [in flask_app.py:47]
2015-06-06 17:37:37,844 ERROR: Exception on /signin_button.png [GET] [in c:\python27\lib\site-packages\flask\app.py:1423]
Traceback (most recent call last):
  File "c:\python27\lib\site-packages\flask\app.py", line 1817, in wsgi_app
    response = self.full_dispatch_request()
  File "c:\python27\lib\site-packages\flask\app.py", line 1477, in full_dispatch_request
    rv = self.handle_user_exception(e)
  File "c:\python27\lib\site-packages\flask\app.py", line 1381, in handle_user_exception
    reraise(exc_type, exc_value, tb)
  File "c:\python27\lib\site-packages\flask\app.py", line 1475, in full_dispatch_request
    rv = self.dispatch_request()
  File "c:\python27\lib\site-packages\flask\app.py", line 1461, in dispatch_request
    return self.view_functions[rule.endpoint](**req.view_args)
  File "flask_app.py", line 335, in signin_button
    return send_file("templates/signin_button.png", mimetype='image/gif')
NameError: global name 'send_file' is not defined
2015-06-06 17:38:02,431 ERROR: Exception on /connect [POST] [in c:\python27\lib\site-packages\flask\app.py:1423]
Traceback (most recent call last):
  File "c:\python27\lib\site-packages\flask\app.py", line 1817, in wsgi_app
    response = self.full_dispatch_request()
  File "c:\python27\lib\site-packages\flask\app.py", line 1477, in full_dispatch_request
    rv = self.handle_user_exception(e)
  File "c:\python27\lib\site-packages\flask\app.py", line 1381, in handle_user_exception
    reraise(exc_type, exc_value, tb)
  File "c:\python27\lib\site-packages\flask\app.py", line 1475, in full_dispatch_request
    rv = self.dispatch_request()
  File "c:\python27\lib\site-packages\flask\app.py", line 1461, in dispatch_request
    return self.view_functions[rule.endpoint](**req.view_args)
  File "flask_app.py", line 360, in connect
    except FlowExchangeError:
NameError: global name 'FlowExchangeError' is not defined
2015-06-06 17:50:04,332 WARNING: to init Login Manager subsystem [in flask_app.py:47]
2015-06-06 17:50:12,226 ERROR: Exception on /signin_button.png [GET] [in c:\python27\lib\site-packages\flask\app.py:1423]
Traceback (most recent call last):
  File "c:\python27\lib\site-packages\flask\app.py", line 1817, in wsgi_app
    response = self.full_dispatch_request()
  File "c:\python27\lib\site-packages\flask\app.py", line 1477, in full_dispatch_request
    rv = self.handle_user_exception(e)
  File "c:\python27\lib\site-packages\flask\app.py", line 1381, in handle_user_exception
    reraise(exc_type, exc_value, tb)
  File "c:\python27\lib\site-packages\flask\app.py", line 1475, in full_dispatch_request
    rv = self.dispatch_request()
  File "c:\python27\lib\site-packages\flask\app.py", line 1461, in dispatch_request
    return self.view_functions[rule.endpoint](**req.view_args)
  File "flask_app.py", line 335, in signin_button
    return send_file("templates/signin_button.png", mimetype='image/gif')
NameError: global name 'send_file' is not defined
2015-06-06 17:50:12,769 ERROR: Exception on /signin_button.png [GET] [in c:\python27\lib\site-packages\flask\app.py:1423]
Traceback (most recent call last):
  File "c:\python27\lib\site-packages\flask\app.py", line 1817, in wsgi_app
    response = self.full_dispatch_request()
  File "c:\python27\lib\site-packages\flask\app.py", line 1477, in full_dispatch_request
    rv = self.handle_user_exception(e)
  File "c:\python27\lib\site-packages\flask\app.py", line 1381, in handle_user_exception
    reraise(exc_type, exc_value, tb)
  File "c:\python27\lib\site-packages\flask\app.py", line 1475, in full_dispatch_request
    rv = self.dispatch_request()
  File "c:\python27\lib\site-packages\flask\app.py", line 1461, in dispatch_request
    return self.view_functions[rule.endpoint](**req.view_args)
  File "flask_app.py", line 335, in signin_button
    return send_file("templates/signin_button.png", mimetype='image/gif')
NameError: global name 'send_file' is not defined
2015-06-06 17:50:15,378 ERROR: Exception on /signin_button.png [GET] [in c:\python27\lib\site-packages\flask\app.py:1423]
Traceback (most recent call last):
  File "c:\python27\lib\site-packages\flask\app.py", line 1817, in wsgi_app
    response = self.full_dispatch_request()
  File "c:\python27\lib\site-packages\flask\app.py", line 1477, in full_dispatch_request
    rv = self.handle_user_exception(e)
  File "c:\python27\lib\site-packages\flask\app.py", line 1381, in handle_user_exception
    reraise(exc_type, exc_value, tb)
  File "c:\python27\lib\site-packages\flask\app.py", line 1475, in full_dispatch_request
    rv = self.dispatch_request()
  File "c:\python27\lib\site-packages\flask\app.py", line 1461, in dispatch_request
    return self.view_functions[rule.endpoint](**req.view_args)
  File "flask_app.py", line 335, in signin_button
    return send_file("templates/signin_button.png", mimetype='image/gif')
NameError: global name 'send_file' is not defined
2015-06-06 17:50:15,818 ERROR: Exception on /signin_button.png [GET] [in c:\python27\lib\site-packages\flask\app.py:1423]
Traceback (most recent call last):
  File "c:\python27\lib\site-packages\flask\app.py", line 1817, in wsgi_app
    response = self.full_dispatch_request()
  File "c:\python27\lib\site-packages\flask\app.py", line 1477, in full_dispatch_request
    rv = self.handle_user_exception(e)
  File "c:\python27\lib\site-packages\flask\app.py", line 1381, in handle_user_exception
    reraise(exc_type, exc_value, tb)
  File "c:\python27\lib\site-packages\flask\app.py", line 1475, in full_dispatch_request
    rv = self.dispatch_request()
  File "c:\python27\lib\site-packages\flask\app.py", line 1461, in dispatch_request
    return self.view_functions[rule.endpoint](**req.view_args)
  File "flask_app.py", line 335, in signin_button
    return send_file("templates/signin_button.png", mimetype='image/gif')
NameError: global name 'send_file' is not defined
2015-06-06 17:53:48,236 WARNING: to init Login Manager subsystem [in flask_app.py:53]
2015-06-06 17:55:34,486 WARNING: to init Login Manager subsystem [in flask_app.py:53]
2015-06-06 18:08:42,434 WARNING: to init Login Manager subsystem [in flask_app.py:53]
2015-06-06 18:44:06,213 WARNING: to init Login Manager subsystem [in flask_app.py:53]
2015-06-07 07:39:33,546 ERROR: Exception on /people [GET] [in c:\python27\lib\site-packages\flask\app.py:1423]
Traceback (most recent call last):
  File "c:\python27\lib\site-packages\flask\app.py", line 1817, in wsgi_app
    response = self.full_dispatch_request()
  File "c:\python27\lib\site-packages\flask\app.py", line 1477, in full_dispatch_request
    rv = self.handle_user_exception(e)
  File "c:\python27\lib\site-packages\flask\app.py", line 1381, in handle_user_exception
    reraise(exc_type, exc_value, tb)
  File "c:\python27\lib\site-packages\flask\app.py", line 1475, in full_dispatch_request
    rv = self.dispatch_request()
  File "c:\python27\lib\site-packages\flask\app.py", line 1461, in dispatch_request
    return self.view_functions[rule.endpoint](**req.view_args)
  File "flask_app.py", line 448, in people
    return response
  File "flask_app.py", line 448, in people
    return response
  File "c:\python27\lib\bdb.py", line 49, in trace_dispatch
    return self.dispatch_line(frame)
  File "c:\python27\lib\bdb.py", line 68, in dispatch_line
    if self.quitting: raise BdbQuit
BdbQuit
2015-06-07 08:23:48,177 WARNING: to init Login Manager subsystem [in flask_app.py:53]
2015-06-07 12:38:59,338 WARNING: to init Login Manager subsystem [in flask_app.py:53]
2015-06-07 15:35:56,848 ERROR: Exception on /people [GET] [in c:\python27\lib\site-packages\flask\app.py:1423]
Traceback (most recent call last):
  File "c:\python27\lib\site-packages\flask\app.py", line 1817, in wsgi_app
    response = self.full_dispatch_request()
  File "c:\python27\lib\site-packages\flask\app.py", line 1477, in full_dispatch_request
    rv = self.handle_user_exception(e)
  File "c:\python27\lib\site-packages\flask\app.py", line 1381, in handle_user_exception
    reraise(exc_type, exc_value, tb)
  File "c:\python27\lib\site-packages\flask\app.py", line 1475, in full_dispatch_request
    rv = self.dispatch_request()
  File "c:\python27\lib\site-packages\flask\app.py", line 1461, in dispatch_request
    return self.view_functions[rule.endpoint](**req.view_args)
  File "flask_app.py", line 449, in people
    # this app. Not all id will give the email addr as some of those
  File "flask_app.py", line 449, in people
    # this app. Not all id will give the email addr as some of those
  File "c:\python27\lib\bdb.py", line 49, in trace_dispatch
    return self.dispatch_line(frame)
  File "c:\python27\lib\bdb.py", line 68, in dispatch_line
    if self.quitting: raise BdbQuit
BdbQuit
2015-06-07 15:35:57,338 ERROR: Exception on /people [GET] [in c:\python27\lib\site-packages\flask\app.py:1423]
Traceback (most recent call last):
  File "c:\python27\lib\site-packages\flask\app.py", line 1817, in wsgi_app
    response = self.full_dispatch_request()
  File "c:\python27\lib\site-packages\flask\app.py", line 1477, in full_dispatch_request
    rv = self.handle_user_exception(e)
  File "c:\python27\lib\site-packages\flask\app.py", line 1381, in handle_user_exception
    reraise(exc_type, exc_value, tb)
  File "c:\python27\lib\site-packages\flask\app.py", line 1475, in full_dispatch_request
    rv = self.dispatch_request()
  File "c:\python27\lib\site-packages\flask\app.py", line 1461, in dispatch_request
    return self.view_functions[rule.endpoint](**req.view_args)
  File "flask_app.py", line 442, in people
    list_result = google_request.execute(http=http)
  File "c:\python27\lib\site-packages\oauth2client\util.py", line 128, in positional_wrapper
    return wrapped(*args, **kwargs)
  File "c:\python27\lib\site-packages\apiclient\http.py", line 676, in execute
    body=self.body, headers=self.headers)
  File "c:\python27\lib\site-packages\oauth2client\util.py", line 128, in positional_wrapper
    return wrapped(*args, **kwargs)
  File "c:\python27\lib\site-packages\oauth2client\client.py", line 494, in new_request
    self._refresh(request_orig)
  File "c:\python27\lib\site-packages\oauth2client\client.py", line 653, in _refresh
    self._do_refresh_request(http_request)
  File "c:\python27\lib\site-packages\oauth2client\client.py", line 682, in _do_refresh_request
    self.token_uri, method='POST', body=body, headers=headers)
  File "c:\python27\lib\site-packages\httplib2\__init__.py", line 1570, in request
    (response, content) = self._request(conn, authority, uri, request_uri, method, body, headers, redirections, cachekey)
  File "c:\python27\lib\site-packages\httplib2\__init__.py", line 1317, in _request
    (response, content) = self._conn_request(conn, request_uri, method, body, headers)
  File "c:\python27\lib\site-packages\httplib2\__init__.py", line 1286, in _conn_request
    response = conn.getresponse()
  File "c:\python27\lib\httplib.py", line 1055, in getresponse
    raise ResponseNotReady()
ResponseNotReady
2015-06-07 22:29:26,269 WARNING: to init Login Manager subsystem [in flask_app.py:53]
2015-06-07 22:30:21,913 WARNING: to init Login Manager subsystem [in flask_app.py:53]
2015-06-07 22:30:22,252 WARNING: user name already exists for haribcva@gmail.com just updating [in library.py:129]
2015-06-07 22:38:19,776 ERROR: Exception on /people [GET] [in c:\python27\lib\site-packages\flask\app.py:1423]
Traceback (most recent call last):
  File "c:\python27\lib\site-packages\flask\app.py", line 1817, in wsgi_app
    response = self.full_dispatch_request()
  File "c:\python27\lib\site-packages\flask\app.py", line 1477, in full_dispatch_request
    rv = self.handle_user_exception(e)
  File "c:\python27\lib\site-packages\flask\app.py", line 1381, in handle_user_exception
    reraise(exc_type, exc_value, tb)
  File "c:\python27\lib\site-packages\flask\app.py", line 1475, in full_dispatch_request
    rv = self.dispatch_request()
  File "c:\python27\lib\site-packages\flask\app.py", line 1461, in dispatch_request
    return self.view_functions[rule.endpoint](**req.view_args)
  File "flask_app.py", line 487, in people
    except AccessTokenRefreshError:
  File "flask_app.py", line 487, in people
    except AccessTokenRefreshError:
  File "c:\python27\lib\bdb.py", line 49, in trace_dispatch
    return self.dispatch_line(frame)
  File "c:\python27\lib\bdb.py", line 68, in dispatch_line
    if self.quitting: raise BdbQuit
BdbQuit
2015-06-07 22:38:20,427 WARNING: user name already exists for haribcva@gmail.com just updating [in library.py:129]
2015-06-07 22:38:20,608 ERROR: Exception on /people [GET] [in c:\python27\lib\site-packages\flask\app.py:1423]
Traceback (most recent call last):
  File "c:\python27\lib\site-packages\flask\app.py", line 1817, in wsgi_app
    response = self.full_dispatch_request()
  File "c:\python27\lib\site-packages\flask\app.py", line 1477, in full_dispatch_request
    rv = self.handle_user_exception(e)
  File "c:\python27\lib\site-packages\flask\app.py", line 1381, in handle_user_exception
    reraise(exc_type, exc_value, tb)
  File "c:\python27\lib\site-packages\flask\app.py", line 1475, in full_dispatch_request
    rv = self.dispatch_request()
  File "c:\python27\lib\site-packages\flask\app.py", line 1461, in dispatch_request
    return self.view_functions[rule.endpoint](**req.view_args)
  File "flask_app.py", line 470, in people
    id = list_result.get('items')[i].get('id')
TypeError: 'NoneType' object has no attribute '__getitem__'
2015-06-07 22:38:58,065 WARNING: to init Login Manager subsystem [in flask_app.py:53]
2015-06-07 22:39:15,377 WARNING: to init Login Manager subsystem [in flask_app.py:53]
2015-06-07 22:39:15,802 WARNING: user name already exists for haribcva@gmail.com just updating [in library.py:129]
2015-06-07 22:42:06,938 ERROR: Exception on /people [GET] [in c:\python27\lib\site-packages\flask\app.py:1423]
Traceback (most recent call last):
  File "c:\python27\lib\site-packages\flask\app.py", line 1817, in wsgi_app
    response = self.full_dispatch_request()
  File "c:\python27\lib\site-packages\flask\app.py", line 1477, in full_dispatch_request
    rv = self.handle_user_exception(e)
  File "c:\python27\lib\site-packages\flask\app.py", line 1381, in handle_user_exception
    reraise(exc_type, exc_value, tb)
  File "c:\python27\lib\site-packages\flask\app.py", line 1475, in full_dispatch_request
    rv = self.dispatch_request()
  File "c:\python27\lib\site-packages\flask\app.py", line 1461, in dispatch_request
    return self.view_functions[rule.endpoint](**req.view_args)
  File "flask_app.py", line 473, in people
    email_arr = get_result.get('emails')
  File "c:\python27\lib\bdb.py", line 55, in trace_dispatch
    return self.dispatch_exception(frame, arg)
  File "c:\python27\lib\bdb.py", line 97, in dispatch_exception
    if self.quitting: raise BdbQuit
BdbQuit
2015-06-07 22:42:07,710 WARNING: user name already exists for haribcva@gmail.com just updating [in library.py:129]
2015-06-07 22:42:07,880 ERROR: Exception on /people [GET] [in c:\python27\lib\site-packages\flask\app.py:1423]
Traceback (most recent call last):
  File "c:\python27\lib\site-packages\flask\app.py", line 1817, in wsgi_app
    response = self.full_dispatch_request()
  File "c:\python27\lib\site-packages\flask\app.py", line 1477, in full_dispatch_request
    rv = self.handle_user_exception(e)
  File "c:\python27\lib\site-packages\flask\app.py", line 1381, in handle_user_exception
    reraise(exc_type, exc_value, tb)
  File "c:\python27\lib\site-packages\flask\app.py", line 1475, in full_dispatch_request
    rv = self.dispatch_request()
  File "c:\python27\lib\site-packages\flask\app.py", line 1461, in dispatch_request
    return self.view_functions[rule.endpoint](**req.view_args)
  File "flask_app.py", line 473, in people
    email_arr = get_result.get('emails')
TypeError: 'NoneType' object has no attribute '__getitem__'
2015-06-07 22:42:42,930 WARNING: to init Login Manager subsystem [in flask_app.py:53]
2015-06-07 22:42:58,653 WARNING: to init Login Manager subsystem [in flask_app.py:53]
2015-06-07 22:42:59,091 WARNING: user name already exists for haribcva@gmail.com just updating [in library.py:129]
2015-06-07 22:43:42,424 WARNING: user name already exists for haribcva@gmail.com just updating [in library.py:129]
2015-06-07 22:44:29,336 WARNING: to init Login Manager subsystem [in flask_app.py:53]
2015-06-07 22:44:43,424 WARNING: to init Login Manager subsystem [in C:\Users\haribala\Documents\GitHub\my_lib_app\flask_app.py:53]
2015-06-07 22:44:43,858 WARNING: user name already exists for haribcva@gmail.com just updating [in C:\Users\haribala\Documents\GitHub\my_lib_app\library.py:129]
2015-06-07 22:44:45,493 WARNING: user name already exists for haribcva@gmail.com just updating [in C:\Users\haribala\Documents\GitHub\my_lib_app\library.py:129]
2015-06-08 18:39:04,523 WARNING: to init Login Manager subsystem [in flask_app.py:53]
2015-06-08 18:40:21,720 WARNING: to init Login Manager subsystem [in C:\Users\haribala\Documents\GitHub\my_lib_app\flask_app.py:53]
2015-06-08 18:40:22,334 WARNING: user name already exists for haribcva@gmail.com just updating [in C:\Users\haribala\Documents\GitHub\my_lib_app\library.py:129]
2015-06-08 18:40:24,148 WARNING: user name already exists for haribcva@gmail.com just updating [in C:\Users\haribala\Documents\GitHub\my_lib_app\library.py:129]
2015-06-08 18:41:21,232 WARNING: user name already exists for haribcva@gmail.com just updating [in C:\Users\haribala\Documents\GitHub\my_lib_app\library.py:129]
2015-06-08 18:41:23,088 WARNING: user name already exists for haribcva@gmail.com just updating [in C:\Users\haribala\Documents\GitHub\my_lib_app\library.py:129]
2015-06-08 18:41:25,266 WARNING: user name already exists for haribcva@gmail.com just updating [in C:\Users\haribala\Documents\GitHub\my_lib_app\library.py:129]
2015-06-08 18:41:26,890 WARNING: user name already exists for haribcva@gmail.com just updating [in C:\Users\haribala\Documents\GitHub\my_lib_app\library.py:129]
2015-06-08 18:44:32,234 WARNING: user name already exists for haribcva@gmail.com just updating [in C:\Users\haribala\Documents\GitHub\my_lib_app\library.py:129]
2015-06-08 18:44:34,410 WARNING: user name already exists for haribcva@gmail.com just updating [in C:\Users\haribala\Documents\GitHub\my_lib_app\library.py:129]
2015-06-08 18:44:36,319 WARNING: user name already exists for haribcva@gmail.com just updating [in C:\Users\haribala\Documents\GitHub\my_lib_app\library.py:129]
2015-06-08 18:44:37,885 WARNING: user name already exists for haribcva@gmail.com just updating [in C:\Users\haribala\Documents\GitHub\my_lib_app\library.py:129]
2015-06-08 18:46:35,357 WARNING: user name already exists for haribcva@gmail.com just updating [in C:\Users\haribala\Documents\GitHub\my_lib_app\library.py:129]
2015-06-08 18:46:36,989 WARNING: user name already exists for haribcva@gmail.com just updating [in C:\Users\haribala\Documents\GitHub\my_lib_app\library.py:129]
2015-06-08 18:46:38,829 WARNING: user name already exists for haribcva@gmail.com just updating [in C:\Users\haribala\Documents\GitHub\my_lib_app\library.py:129]
2015-06-08 18:46:42,214 WARNING: user name already exists for haribcva@gmail.com just updating [in C:\Users\haribala\Documents\GitHub\my_lib_app\library.py:129]
2015-06-08 18:47:11,298 WARNING: user name already exists for haribcva@gmail.com just updating [in C:\Users\haribala\Documents\GitHub\my_lib_app\library.py:129]
2015-06-08 18:47:12,865 WARNING: user name already exists for haribcva@gmail.com just updating [in C:\Users\haribala\Documents\GitHub\my_lib_app\library.py:129]
2015-06-08 18:47:14,269 WARNING: user name already exists for haribcva@gmail.com just updating [in C:\Users\haribala\Documents\GitHub\my_lib_app\library.py:129]
2015-06-08 18:47:16,819 WARNING: user name already exists for haribcva@gmail.com just updating [in C:\Users\haribala\Documents\GitHub\my_lib_app\library.py:129]
2015-06-08 18:51:40,278 WARNING: user name already exists for haribcva@gmail.com just updating [in C:\Users\haribala\Documents\GitHub\my_lib_app\library.py:129]
2015-06-08 18:51:41,884 WARNING: user name already exists for haribcva@gmail.com just updating [in C:\Users\haribala\Documents\GitHub\my_lib_app\library.py:129]
2015-06-08 18:51:43,542 WARNING: user name already exists for haribcva@gmail.com just updating [in C:\Users\haribala\Documents\GitHub\my_lib_app\library.py:129]
2015-06-08 18:51:45,161 WARNING: user name already exists for haribcva@gmail.com just updating [in C:\Users\haribala\Documents\GitHub\my_lib_app\library.py:129]
2015-06-08 18:52:24,421 WARNING: user name already exists for haribcva@gmail.com just updating [in C:\Users\haribala\Documents\GitHub\my_lib_app\library.py:129]
2015-06-08 18:52:26,052 WARNING: user name already exists for haribcva@gmail.com just updating [in C:\Users\haribala\Documents\GitHub\my_lib_app\library.py:129]
2015-06-08 18:52:28,525 WARNING: user name already exists for haribcva@gmail.com just updating [in C:\Users\haribala\Documents\GitHub\my_lib_app\library.py:129]
2015-06-08 18:52:30,029 WARNING: user name already exists for haribcva@gmail.com just updating [in C:\Users\haribala\Documents\GitHub\my_lib_app\library.py:129]
2015-06-08 19:11:15,295 WARNING: user name already exists for haribcva@gmail.com just updating [in C:\Users\haribala\Documents\GitHub\my_lib_app\library.py:129]
2015-06-08 19:11:16,914 WARNING: user name already exists for haribcva@gmail.com just updating [in C:\Users\haribala\Documents\GitHub\my_lib_app\library.py:129]
2015-06-08 19:11:18,315 WARNING: user name already exists for haribcva@gmail.com just updating [in C:\Users\haribala\Documents\GitHub\my_lib_app\library.py:129]
2015-06-08 19:11:19,690 WARNING: user name already exists for haribcva@gmail.com just updating [in C:\Users\haribala\Documents\GitHub\my_lib_app\library.py:129]
2015-06-08 19:15:44,190 WARNING: user name already exists for haribcva@gmail.com just updating [in C:\Users\haribala\Documents\GitHub\my_lib_app\library.py:129]
2015-06-08 19:15:45,858 WARNING: user name already exists for haribcva@gmail.com just updating [in C:\Users\haribala\Documents\GitHub\my_lib_app\library.py:129]
2015-06-08 19:15:47,418 WARNING: user name already exists for haribcva@gmail.com just updating [in C:\Users\haribala\Documents\GitHub\my_lib_app\library.py:129]
2015-06-08 19:17:59,270 WARNING: user name already exists for haribcva@gmail.com just updating [in C:\Users\haribala\Documents\GitHub\my_lib_app\library.py:129]
2015-06-08 19:26:58,993 WARNING: to init Login Manager subsystem [in flask_app.py:53]
2015-06-08 19:27:16,857 WARNING: to init Login Manager subsystem [in C:\Users\haribala\Documents\GitHub\my_lib_app\flask_app.py:53]
2015-06-08 19:27:17,242 WARNING: user name already exists for haribcva@gmail.com just updating [in C:\Users\haribala\Documents\GitHub\my_lib_app\library.py:129]
2015-06-19 15:12:49,683 WARNING: to init Login Manager subsystem [in flask_app.py:55]
2015-06-19 15:19:49,743 WARNING: to init Login Manager subsystem [in flask_app.py:55]
2015-06-19 15:20:13,378 WARNING: to init Login Manager subsystem [in C:\Users\haribala\Documents\GitHub\my_lib_app\flask_app.py:55]
2015-06-19 15:20:13,555 WARNING: user name already exists for haribcva@gmail.com just updating [in C:\Users\haribala\Documents\GitHub\my_lib_app\library.py:23]
2015-06-19 15:27:03,056 WARNING: to init Login Manager subsystem [in flask_app.py:55]
2015-06-19 15:27:18,631 WARNING: to init Login Manager subsystem [in C:\Users\haribala\Documents\GitHub\my_lib_app\flask_app.py:55]
2015-06-19 15:27:18,792 WARNING: user name already exists for haribcva@gmail.com just updating [in C:\Users\haribala\Documents\GitHub\my_lib_app\library.py:23]
2015-06-19 15:31:26,062 WARNING: to init Login Manager subsystem [in flask_app.py:55]
2015-06-19 15:31:41,956 WARNING: to init Login Manager subsystem [in flask_app.py:55]
2015-06-19 15:31:42,170 WARNING: user name already exists for haribcva@gmail.com just updating [in library.py:23]
2015-06-19 15:36:25,223 WARNING: user name already exists for haribcva@gmail.com just updating [in library.py:23]
2015-06-19 15:36:28,654 WARNING: user name already exists for haribcva@gmail.com just updating [in library.py:23]
2015-06-19 15:36:32,588 WARNING: user name already exists for haribcva@gmail.com just updating [in library.py:23]
2015-06-19 15:36:43,010 WARNING: user name already exists for haribcva@gmail.com just updating [in library.py:23]
2015-06-19 15:36:52,565 WARNING: user name already exists for haribcva@gmail.com just updating [in library.py:23]
2015-06-19 15:37:50,802 WARNING: user name already exists for haribcva@gmail.com just updating [in library.py:23]
2015-06-19 15:37:56,474 WARNING: user name already exists for haribcva@gmail.com just updating [in library.py:23]
2015-06-19 15:38:05,661 WARNING: user name already exists for haribcva@gmail.com just updating [in library.py:23]
2015-06-19 15:38:11,367 WARNING: user name already exists for haribcva@gmail.com just updating [in library.py:23]
2015-06-19 15:40:57,154 WARNING: to init Login Manager subsystem [in flask_app.py:55]
2015-06-19 15:41:00,914 WARNING: to init Login Manager subsystem [in flask_app.py:55]
2015-06-19 15:41:05,632 WARNING: to init Login Manager subsystem [in flask_app.py:55]
2015-06-19 15:41:21,733 WARNING: to init Login Manager subsystem [in flask_app.py:55]
2015-06-19 15:42:15,744 WARNING: to init Login Manager subsystem [in flask_app.py:55]
2015-06-19 15:44:40,413 WARNING: to init Login Manager subsystem [in C:\Users\haribala\Documents\GitHub\my_lib_app\flask_app.py:55]
2015-06-19 15:44:40,595 WARNING: user name already exists for haribcva@gmail.com just updating [in C:\Users\haribala\Documents\GitHub\my_lib_app\library.py:23]
2015-06-19 15:50:55,622 WARNING: to init Login Manager subsystem [in flask_app.py:55]
2015-06-19 15:51:11,680 WARNING: to init Login Manager subsystem [in C:\Users\haribala\Documents\GitHub\my_lib_app\flask_app.py:55]
2015-06-19 15:51:11,865 WARNING: user name already exists for haribcva@gmail.com just updating [in C:\Users\haribala\Documents\GitHub\my_lib_app\library.py:23]
2015-06-19 15:54:21,687 WARNING: to init Login Manager subsystem [in flask_app.py:55]
2015-06-19 15:59:00,023 WARNING: to init Login Manager subsystem [in flask_app.py:55]
2015-06-19 15:59:16,687 WARNING: to init Login Manager subsystem [in C:\Users\haribala\Documents\GitHub\my_lib_app\flask_app.py:55]
2015-06-19 15:59:16,868 WARNING: user name already exists for haribcva@gmail.com just updating [in C:\Users\haribala\Documents\GitHub\my_lib_app\library.py:23]
2015-06-19 16:00:18,302 WARNING: to init Login Manager subsystem [in flask_app.py:55]
2015-06-19 16:00:30,407 WARNING: to init Login Manager subsystem [in C:\Users\haribala\Documents\GitHub\my_lib_app\flask_app.py:55]
2015-06-19 16:00:30,822 WARNING: user name already exists for haribcva@gmail.com just updating [in C:\Users\haribala\Documents\GitHub\my_lib_app\library.py:23]
2015-06-19 16:08:06,028 WARNING: to init Login Manager subsystem [in flask_app.py:55]
2015-06-19 16:09:08,177 WARNING: to init Login Manager subsystem [in flask_app.py:55]
2015-06-19 16:11:10,753 WARNING: to init Login Manager subsystem [in flask_app.py:55]
2015-06-19 16:11:21,875 WARNING: to init Login Manager subsystem [in C:\Users\haribala\Documents\GitHub\my_lib_app\flask_app.py:55]
2015-06-19 16:11:22,059 WARNING: user name already exists for haribcva@gmail.com just updating [in C:\Users\haribala\Documents\GitHub\my_lib_app\library.py:23]
2015-06-19 16:12:39,711 WARNING: to init Login Manager subsystem [in flask_app.py:55]
2015-06-19 16:13:53,596 WARNING: to init Login Manager subsystem [in flask_app.py:55]
2015-06-19 16:14:52,984 WARNING: to init Login Manager subsystem [in C:\Users\haribala\Documents\GitHub\my_lib_app\flask_app.py:55]
2015-06-19 16:14:53,163 WARNING: user name already exists for haribcva@gmail.com just updating [in C:\Users\haribala\Documents\GitHub\my_lib_app\library.py:23]
2015-06-19 16:16:32,473 WARNING: to init Login Manager subsystem [in flask_app.py:55]
2015-06-19 16:16:45,509 WARNING: to init Login Manager subsystem [in C:\Users\haribala\Documents\GitHub\my_lib_app\flask_app.py:55]
2015-06-19 16:16:45,694 WARNING: user name already exists for haribcva@gmail.com just updating [in C:\Users\haribala\Documents\GitHub\my_lib_app\library.py:23]
2015-06-21 07:55:02,947 WARNING: to init Login Manager subsystem [in flask_app.py:55]
2015-06-21 07:55:26,746 WARNING: to init Login Manager subsystem [in C:\Users\haribala\Documents\GitHub\my_lib_app\flask_app.py:55]
2015-06-21 07:55:26,913 WARNING: user name already exists for haribcva@gmail.com just updating [in C:\Users\haribala\Documents\GitHub\my_lib_app\library.py:23]
2015-06-21 09:43:09,486 WARNING: to init Login Manager subsystem [in .\flask_app.py:55]
2015-06-21 09:43:32,846 WARNING: to init Login Manager subsystem [in C:\Users\haribala\Documents\GitHub\my_lib_app\flask_app.py:55]
2015-06-21 09:43:33,043 WARNING: user name already exists for haribcva@gmail.com just updating [in C:\Users\haribala\Documents\GitHub\my_lib_app\library.py:23]
2015-06-21 11:21:35,244 WARNING: to init Login Manager subsystem [in .\flask_app.py:55]
2015-06-21 11:24:58,776 WARNING: to init Login Manager subsystem [in C:\Users\haribala\Documents\GitHub\my_lib_app\flask_app.py:55]
2015-06-21 11:24:59,276 WARNING: user name already exists for haribcva@gmail.com just updating [in C:\Users\haribala\Documents\GitHub\my_lib_app\library.py:23]
2015-06-21 11:25:33,980 WARNING: user name already exists for haribcva@gmail.com just updating [in C:\Users\haribala\Documents\GitHub\my_lib_app\library.py:23]
2015-06-21 11:25:36,089 WARNING: user name already exists for haribcva@gmail.com just updating [in C:\Users\haribala\Documents\GitHub\my_lib_app\library.py:23]
2015-06-21 11:52:50,210 WARNING: to init Login Manager subsystem [in .\flask_app.py:55]
2015-06-21 11:53:19,592 WARNING: to init Login Manager subsystem [in C:\Users\haribala\Documents\GitHub\my_lib_app\flask_app.py:55]
2015-06-21 11:53:19,785 WARNING: user name already exists for haribcva@gmail.com just updating [in C:\Users\haribala\Documents\GitHub\my_lib_app\library.py:23]
2015-06-21 11:53:21,526 WARNING: user name already exists for haribcva@gmail.com just updating [in C:\Users\haribala\Documents\GitHub\my_lib_app\library.py:23]
2015-06-21 11:59:29,650 WARNING: to init Login Manager subsystem [in .\flask_app.py:55]
2015-06-21 12:01:17,983 WARNING: to init Login Manager subsystem [in C:\Users\haribala\Documents\GitHub\my_lib_app\flask_app.py:55]
2015-06-21 12:01:18,155 WARNING: user name already exists for haribcva@gmail.com just updating [in C:\Users\haribala\Documents\GitHub\my_lib_app\library.py:23]
2015-06-21 12:01:19,750 WARNING: user name already exists for haribcva@gmail.com just updating [in C:\Users\haribala\Documents\GitHub\my_lib_app\library.py:23]
2015-06-21 12:05:33,880 WARNING: user name already exists for akshaychitra7@gmail.com just updating [in C:\Users\haribala\Documents\GitHub\my_lib_app\library.py:23]
2015-06-21 12:05:34,756 WARNING: user name already exists for akshaychitra7@gmail.com just updating [in C:\Users\haribala\Documents\GitHub\my_lib_app\library.py:23]
2015-06-21 12:07:07,720 WARNING: user name already exists for haribcva@gmail.com just updating [in C:\Users\haribala\Documents\GitHub\my_lib_app\library.py:23]
2015-06-21 12:07:09,779 WARNING: user name already exists for haribcva@gmail.com just updating [in C:\Users\haribala\Documents\GitHub\my_lib_app\library.py:23]
2015-06-21 12:10:21,151 WARNING: user name already exists for haribcva@gmail.com just updating [in C:\Users\haribala\Documents\GitHub\my_lib_app\library.py:23]
2015-06-21 12:16:26,976 WARNING: user name already exists for haribcva@gmail.com just updating [in C:\Users\haribala\Documents\GitHub\my_lib_app\library.py:23]
